<?xml version="1.0"?>
<robot xmlns:xacro="http://ros.org/wiki/xacro">
    <xacro:include filename="$(find fishbot_description)/urdf/fishbot/common_inertia.xacro"/>
    <xacro:macro name="wheel_xacro" params="wheel_name xyz">
        <!-- 机器人的IMU部件 -->
        <link name="${wheel_name}_link">
            <!-- 部件的外观描述 -->
            <visual>
                <!-- 沿着自己几何中心的偏移和旋转 -->
                <origin xyz="0.0 0.0 0.0" rpy="1.57079 0.0 0.0"/>
                <!-- 几何形状 -->
                <geometry>
                    <!-- 正方体 -->
                    <cylinder radius="0.0325" length="0.04"/>
                </geometry>
                <material name="yellow">
                    <color rgba="1.0 1.0 0.0 0.8"/>
                </material>
            </visual>
            <collision>
                <!-- 沿着自己几何中心的偏移和旋转 -->
                <origin xyz="0.0 0.0 0.0" rpy="1.57079 0.0 0.0"/>
                <!-- 几何形状 -->
                <geometry>
                    <!-- 正方体 -->
                    <cylinder radius="0.0325" length="0.04"/>
                </geometry>
                <material name="yellow">
                    <color rgba="1.0 1.0 0.0 0.8"/>
                </material>
            </collision>
            <xacro:cylinder_inertia m="0.05" r="0.0325" h="0.04"/>
        </link>
        <!-- 机器人的关节，用于组合机器人的部件 -->
        <joint name="${wheel_name}_joint" type="continuous">
            <parent link="base_link" />
            <child link="${wheel_name}_link" />
            <origin xyz="${xyz}" rpy="0 0 0" />
            <!-- 绕y轴旋转 -->
            <axis xyz="0 1 0"/> 
        </joint>

        <gazebo reference="${wheel_name}_link">
            <mu1 value="20.0"/> <!-- 切向摩擦系数 -->
            <mu2 value="20.0"/> <!-- 法向摩擦系数 -->
            <kp value="1000000000.0"/> <!-- 接触的刚度系数 -->
            <kd value="1.0"/> <!-- 阻尼系数 -->
        </gazebo>
    </xacro:macro>
</robot>
